{
 "cells": [
  {
   "cell_type": "code",
   "execution_count": 2,
   "metadata": {},
   "outputs": [],
   "source": [
    "#tipicas\n",
    "import pandas as pd\n",
    "import numpy as np\n",
    "\n",
    "#datagen\n",
    "from keras.preprocessing.image import ImageDataGenerator\n",
    "\n",
    "#modelos\n",
    "from tensorflow.keras import Sequential, layers, models\n",
    "from tensorflow.keras.callbacks import EarlyStopping"
   ]
  },
  {
   "cell_type": "code",
   "execution_count": 3,
   "metadata": {},
   "outputs": [
    {
     "name": "stdout",
     "output_type": "stream",
     "text": [
      "Found 31000 images belonging to 4 classes.\n",
      "Found 8855 images belonging to 4 classes.\n",
      "Found 4433 images belonging to 4 classes.\n"
     ]
    }
   ],
   "source": [
    "train_datagen = ImageDataGenerator(rescale = 1./255)\n",
    "val_datagen = ImageDataGenerator(rescale = 1./255)\n",
    "test_datagen = ImageDataGenerator(rescale=1./255)\n",
    "\n",
    "#creamos los generadores con batch de 30 fotos con el dir correpondiente\n",
    "train_dir = \"/home/vvdiaz1/code/vvdiaz1/automatic_tagging/raw_data/final_split/train\"\n",
    "val_dir = \"/home/vvdiaz1/code/vvdiaz1/automatic_tagging/raw_data/final_split/val\"\n",
    "test_dir = \"/home/vvdiaz1/code/vvdiaz1/automatic_tagging/raw_data/final_split/test\"\n",
    "\n",
    "train_generator = train_datagen.flow_from_directory(\n",
    "                                train_dir,\n",
    "                                target_size =(480, 360), # target_size = input image size\n",
    "                                batch_size = 5,\n",
    "                                class_mode ='categorical')\n",
    "\n",
    "val_generator = train_datagen.flow_from_directory(\n",
    "                                val_dir,\n",
    "                                target_size =(480, 360), # target_size = input image size\n",
    "                                batch_size = 5,\n",
    "                                class_mode ='categorical')\n",
    "\n",
    "test_generator = train_datagen.flow_from_directory(\n",
    "                                test_dir,\n",
    "                                target_size =(480, 360), # target_size = input image size\n",
    "                                batch_size = 5,\n",
    "                                class_mode ='categorical')"
   ]
  },
  {
   "cell_type": "code",
   "execution_count": 5,
   "metadata": {},
   "outputs": [],
   "source": [
    "def load_own_model_master():\n",
    "    model = Sequential()\n",
    "    model.add(layers.Input(shape=(480,360,3), name='input'))\n",
    "    model.add(layers.Conv2D(16, kernel_size=10, activation='relu'))\n",
    "    model.add(layers.MaxPooling2D(3))\n",
    "\n",
    "    model.add(layers.Conv2D(32, kernel_size=8, activation=\"relu\"))\n",
    "    model.add(layers.MaxPooling2D(3))\n",
    "\n",
    "    model.add(layers.Conv2D(32, kernel_size=6, activation=\"relu\"))\n",
    "    model.add(layers.MaxPooling2D(3))\n",
    "\n",
    "    model.add(layers.Flatten())\n",
    "    model.add(layers.Dense(100, activation='relu'))\n",
    "    model.add(layers.Dense(7, activation='softmax'))\n",
    "\n",
    "    model.compile(loss = 'categorical_crossentropy', \n",
    "                    optimizer = 'adam',\n",
    "                    metrics = 'accuracy')\n",
    "    \n",
    "    return model"
   ]
  },
  {
   "cell_type": "code",
   "execution_count": 7,
   "metadata": {},
   "outputs": [
    {
     "name": "stderr",
     "output_type": "stream",
     "text": [
      "2023-01-17 21:13:06.468218: W tensorflow/stream_executor/platform/default/dso_loader.cc:64] Could not load dynamic library 'libcuda.so.1'; dlerror: libcuda.so.1: cannot open shared object file: No such file or directory\n",
      "2023-01-17 21:13:06.469212: W tensorflow/stream_executor/cuda/cuda_driver.cc:263] failed call to cuInit: UNKNOWN ERROR (303)\n",
      "2023-01-17 21:13:06.469861: I tensorflow/stream_executor/cuda/cuda_diagnostics.cc:156] kernel driver does not appear to be running on this host (LAPTOP-HHE71063): /proc/driver/nvidia/version does not exist\n",
      "2023-01-17 21:13:06.474213: I tensorflow/core/platform/cpu_feature_guard.cc:193] This TensorFlow binary is optimized with oneAPI Deep Neural Network Library (oneDNN) to use the following CPU instructions in performance-critical operations:  AVX2 FMA\n",
      "To enable them in other operations, rebuild TensorFlow with the appropriate compiler flags.\n"
     ]
    },
    {
     "name": "stdout",
     "output_type": "stream",
     "text": [
      "Model: \"sequential\"\n",
      "_________________________________________________________________\n",
      " Layer (type)                Output Shape              Param #   \n",
      "=================================================================\n",
      " conv2d (Conv2D)             (None, 471, 351, 16)      4816      \n",
      "                                                                 \n",
      " max_pooling2d (MaxPooling2D  (None, 157, 117, 16)     0         \n",
      " )                                                               \n",
      "                                                                 \n",
      " conv2d_1 (Conv2D)           (None, 150, 110, 32)      32800     \n",
      "                                                                 \n",
      " max_pooling2d_1 (MaxPooling  (None, 50, 36, 32)       0         \n",
      " 2D)                                                             \n",
      "                                                                 \n",
      " conv2d_2 (Conv2D)           (None, 45, 31, 32)        36896     \n",
      "                                                                 \n",
      " max_pooling2d_2 (MaxPooling  (None, 15, 10, 32)       0         \n",
      " 2D)                                                             \n",
      "                                                                 \n",
      " flatten (Flatten)           (None, 4800)              0         \n",
      "                                                                 \n",
      " dense (Dense)               (None, 100)               480100    \n",
      "                                                                 \n",
      " dense_1 (Dense)             (None, 7)                 707       \n",
      "                                                                 \n",
      "=================================================================\n",
      "Total params: 555,319\n",
      "Trainable params: 555,319\n",
      "Non-trainable params: 0\n",
      "_________________________________________________________________\n"
     ]
    }
   ],
   "source": [
    "model = load_own_model_master()\n",
    "model.summary()"
   ]
  },
  {
   "cell_type": "code",
   "execution_count": 11,
   "metadata": {},
   "outputs": [
    {
     "name": "stderr",
     "output_type": "stream",
     "text": [
      "2023-01-17 21:35:05.636060: W tensorflow/core/framework/cpu_allocator_impl.cc:82] Allocation of 52902720 exceeds 10% of free system memory.\n"
     ]
    },
    {
     "ename": "InvalidArgumentError",
     "evalue": "Graph execution error:\n\nDetected at node 'categorical_crossentropy/softmax_cross_entropy_with_logits' defined at (most recent call last):\n    File \"/home/vvdiaz1/.pyenv/versions/3.10.6/lib/python3.10/runpy.py\", line 196, in _run_module_as_main\n      return _run_code(code, main_globals, None,\n    File \"/home/vvdiaz1/.pyenv/versions/3.10.6/lib/python3.10/runpy.py\", line 86, in _run_code\n      exec(code, run_globals)\n    File \"/home/vvdiaz1/.pyenv/versions/lewagon/lib/python3.10/site-packages/ipykernel_launcher.py\", line 17, in <module>\n      app.launch_new_instance()\n    File \"/home/vvdiaz1/.pyenv/versions/lewagon/lib/python3.10/site-packages/traitlets/config/application.py\", line 982, in launch_instance\n      app.start()\n    File \"/home/vvdiaz1/.pyenv/versions/lewagon/lib/python3.10/site-packages/ipykernel/kernelapp.py\", line 712, in start\n      self.io_loop.start()\n    File \"/home/vvdiaz1/.pyenv/versions/lewagon/lib/python3.10/site-packages/tornado/platform/asyncio.py\", line 215, in start\n      self.asyncio_loop.run_forever()\n    File \"/home/vvdiaz1/.pyenv/versions/3.10.6/lib/python3.10/asyncio/base_events.py\", line 600, in run_forever\n      self._run_once()\n    File \"/home/vvdiaz1/.pyenv/versions/3.10.6/lib/python3.10/asyncio/base_events.py\", line 1896, in _run_once\n      handle._run()\n    File \"/home/vvdiaz1/.pyenv/versions/3.10.6/lib/python3.10/asyncio/events.py\", line 80, in _run\n      self._context.run(self._callback, *self._args)\n    File \"/home/vvdiaz1/.pyenv/versions/lewagon/lib/python3.10/site-packages/ipykernel/kernelbase.py\", line 510, in dispatch_queue\n      await self.process_one()\n    File \"/home/vvdiaz1/.pyenv/versions/lewagon/lib/python3.10/site-packages/ipykernel/kernelbase.py\", line 499, in process_one\n      await dispatch(*args)\n    File \"/home/vvdiaz1/.pyenv/versions/lewagon/lib/python3.10/site-packages/ipykernel/kernelbase.py\", line 406, in dispatch_shell\n      await result\n    File \"/home/vvdiaz1/.pyenv/versions/lewagon/lib/python3.10/site-packages/ipykernel/kernelbase.py\", line 730, in execute_request\n      reply_content = await reply_content\n    File \"/home/vvdiaz1/.pyenv/versions/lewagon/lib/python3.10/site-packages/ipykernel/ipkernel.py\", line 383, in do_execute\n      res = shell.run_cell(\n    File \"/home/vvdiaz1/.pyenv/versions/lewagon/lib/python3.10/site-packages/ipykernel/zmqshell.py\", line 528, in run_cell\n      return super().run_cell(*args, **kwargs)\n    File \"/home/vvdiaz1/.pyenv/versions/lewagon/lib/python3.10/site-packages/IPython/core/interactiveshell.py\", line 2885, in run_cell\n      result = self._run_cell(\n    File \"/home/vvdiaz1/.pyenv/versions/lewagon/lib/python3.10/site-packages/IPython/core/interactiveshell.py\", line 2940, in _run_cell\n      return runner(coro)\n    File \"/home/vvdiaz1/.pyenv/versions/lewagon/lib/python3.10/site-packages/IPython/core/async_helpers.py\", line 129, in _pseudo_sync_runner\n      coro.send(None)\n    File \"/home/vvdiaz1/.pyenv/versions/lewagon/lib/python3.10/site-packages/IPython/core/interactiveshell.py\", line 3139, in run_cell_async\n      has_raised = await self.run_ast_nodes(code_ast.body, cell_name,\n    File \"/home/vvdiaz1/.pyenv/versions/lewagon/lib/python3.10/site-packages/IPython/core/interactiveshell.py\", line 3318, in run_ast_nodes\n      if await self.run_code(code, result, async_=asy):\n    File \"/home/vvdiaz1/.pyenv/versions/lewagon/lib/python3.10/site-packages/IPython/core/interactiveshell.py\", line 3378, in run_code\n      exec(code_obj, self.user_global_ns, self.user_ns)\n    File \"/tmp/ipykernel_3689/2842717622.py\", line 1, in <module>\n      history = model.fit_generator(\n    File \"/home/vvdiaz1/.pyenv/versions/lewagon/lib/python3.10/site-packages/keras/engine/training.py\", line 2507, in fit_generator\n      return self.fit(\n    File \"/home/vvdiaz1/.pyenv/versions/lewagon/lib/python3.10/site-packages/keras/utils/traceback_utils.py\", line 65, in error_handler\n      return fn(*args, **kwargs)\n    File \"/home/vvdiaz1/.pyenv/versions/lewagon/lib/python3.10/site-packages/keras/engine/training.py\", line 1564, in fit\n      tmp_logs = self.train_function(iterator)\n    File \"/home/vvdiaz1/.pyenv/versions/lewagon/lib/python3.10/site-packages/keras/engine/training.py\", line 1160, in train_function\n      return step_function(self, iterator)\n    File \"/home/vvdiaz1/.pyenv/versions/lewagon/lib/python3.10/site-packages/keras/engine/training.py\", line 1146, in step_function\n      outputs = model.distribute_strategy.run(run_step, args=(data,))\n    File \"/home/vvdiaz1/.pyenv/versions/lewagon/lib/python3.10/site-packages/keras/engine/training.py\", line 1135, in run_step\n      outputs = model.train_step(data)\n    File \"/home/vvdiaz1/.pyenv/versions/lewagon/lib/python3.10/site-packages/keras/engine/training.py\", line 994, in train_step\n      loss = self.compute_loss(x, y, y_pred, sample_weight)\n    File \"/home/vvdiaz1/.pyenv/versions/lewagon/lib/python3.10/site-packages/keras/engine/training.py\", line 1052, in compute_loss\n      return self.compiled_loss(\n    File \"/home/vvdiaz1/.pyenv/versions/lewagon/lib/python3.10/site-packages/keras/engine/compile_utils.py\", line 265, in __call__\n      loss_value = loss_obj(y_t, y_p, sample_weight=sw)\n    File \"/home/vvdiaz1/.pyenv/versions/lewagon/lib/python3.10/site-packages/keras/losses.py\", line 152, in __call__\n      losses = call_fn(y_true, y_pred)\n    File \"/home/vvdiaz1/.pyenv/versions/lewagon/lib/python3.10/site-packages/keras/losses.py\", line 272, in call\n      return ag_fn(y_true, y_pred, **self._fn_kwargs)\n    File \"/home/vvdiaz1/.pyenv/versions/lewagon/lib/python3.10/site-packages/keras/losses.py\", line 1990, in categorical_crossentropy\n      return backend.categorical_crossentropy(\n    File \"/home/vvdiaz1/.pyenv/versions/lewagon/lib/python3.10/site-packages/keras/backend.py\", line 5535, in categorical_crossentropy\n      return tf.nn.softmax_cross_entropy_with_logits(\nNode: 'categorical_crossentropy/softmax_cross_entropy_with_logits'\nlogits and labels must be broadcastable: logits_size=[5,7] labels_size=[5,4]\n\t [[{{node categorical_crossentropy/softmax_cross_entropy_with_logits}}]] [Op:__inference_train_function_923]",
     "output_type": "error",
     "traceback": [
      "\u001b[0;31m---------------------------------------------------------------------------\u001b[0m",
      "\u001b[0;31mInvalidArgumentError\u001b[0m                      Traceback (most recent call last)",
      "Cell \u001b[0;32mIn [11], line 1\u001b[0m\n\u001b[0;32m----> 1\u001b[0m history \u001b[39m=\u001b[39m model\u001b[39m.\u001b[39;49mfit(\n\u001b[1;32m      2\u001b[0m              train_generator,\n\u001b[1;32m      3\u001b[0m              steps_per_epoch \u001b[39m=\u001b[39;49m \u001b[39m5\u001b[39;49m,\n\u001b[1;32m      4\u001b[0m             \u001b[39m#  epochs = 30,\u001b[39;49;00m\n\u001b[1;32m      5\u001b[0m              callbacks \u001b[39m=\u001b[39;49m EarlyStopping(patience \u001b[39m=\u001b[39;49m \u001b[39m5\u001b[39;49m, restore_best_weights\u001b[39m=\u001b[39;49m\u001b[39mTrue\u001b[39;49;00m),\n\u001b[1;32m      6\u001b[0m              validation_data \u001b[39m=\u001b[39;49m val_generator,\n\u001b[1;32m      7\u001b[0m              validation_steps \u001b[39m=\u001b[39;49m \u001b[39m15\u001b[39;49m)\n",
      "File \u001b[0;32m~/.pyenv/versions/lewagon/lib/python3.10/site-packages/keras/utils/traceback_utils.py:70\u001b[0m, in \u001b[0;36mfilter_traceback.<locals>.error_handler\u001b[0;34m(*args, **kwargs)\u001b[0m\n\u001b[1;32m     67\u001b[0m     filtered_tb \u001b[39m=\u001b[39m _process_traceback_frames(e\u001b[39m.\u001b[39m__traceback__)\n\u001b[1;32m     68\u001b[0m     \u001b[39m# To get the full stack trace, call:\u001b[39;00m\n\u001b[1;32m     69\u001b[0m     \u001b[39m# `tf.debugging.disable_traceback_filtering()`\u001b[39;00m\n\u001b[0;32m---> 70\u001b[0m     \u001b[39mraise\u001b[39;00m e\u001b[39m.\u001b[39mwith_traceback(filtered_tb) \u001b[39mfrom\u001b[39;00m \u001b[39mNone\u001b[39m\n\u001b[1;32m     71\u001b[0m \u001b[39mfinally\u001b[39;00m:\n\u001b[1;32m     72\u001b[0m     \u001b[39mdel\u001b[39;00m filtered_tb\n",
      "File \u001b[0;32m~/.pyenv/versions/lewagon/lib/python3.10/site-packages/tensorflow/python/eager/execute.py:54\u001b[0m, in \u001b[0;36mquick_execute\u001b[0;34m(op_name, num_outputs, inputs, attrs, ctx, name)\u001b[0m\n\u001b[1;32m     52\u001b[0m \u001b[39mtry\u001b[39;00m:\n\u001b[1;32m     53\u001b[0m   ctx\u001b[39m.\u001b[39mensure_initialized()\n\u001b[0;32m---> 54\u001b[0m   tensors \u001b[39m=\u001b[39m pywrap_tfe\u001b[39m.\u001b[39mTFE_Py_Execute(ctx\u001b[39m.\u001b[39m_handle, device_name, op_name,\n\u001b[1;32m     55\u001b[0m                                       inputs, attrs, num_outputs)\n\u001b[1;32m     56\u001b[0m \u001b[39mexcept\u001b[39;00m core\u001b[39m.\u001b[39m_NotOkStatusException \u001b[39mas\u001b[39;00m e:\n\u001b[1;32m     57\u001b[0m   \u001b[39mif\u001b[39;00m name \u001b[39mis\u001b[39;00m \u001b[39mnot\u001b[39;00m \u001b[39mNone\u001b[39;00m:\n",
      "\u001b[0;31mInvalidArgumentError\u001b[0m: Graph execution error:\n\nDetected at node 'categorical_crossentropy/softmax_cross_entropy_with_logits' defined at (most recent call last):\n    File \"/home/vvdiaz1/.pyenv/versions/3.10.6/lib/python3.10/runpy.py\", line 196, in _run_module_as_main\n      return _run_code(code, main_globals, None,\n    File \"/home/vvdiaz1/.pyenv/versions/3.10.6/lib/python3.10/runpy.py\", line 86, in _run_code\n      exec(code, run_globals)\n    File \"/home/vvdiaz1/.pyenv/versions/lewagon/lib/python3.10/site-packages/ipykernel_launcher.py\", line 17, in <module>\n      app.launch_new_instance()\n    File \"/home/vvdiaz1/.pyenv/versions/lewagon/lib/python3.10/site-packages/traitlets/config/application.py\", line 982, in launch_instance\n      app.start()\n    File \"/home/vvdiaz1/.pyenv/versions/lewagon/lib/python3.10/site-packages/ipykernel/kernelapp.py\", line 712, in start\n      self.io_loop.start()\n    File \"/home/vvdiaz1/.pyenv/versions/lewagon/lib/python3.10/site-packages/tornado/platform/asyncio.py\", line 215, in start\n      self.asyncio_loop.run_forever()\n    File \"/home/vvdiaz1/.pyenv/versions/3.10.6/lib/python3.10/asyncio/base_events.py\", line 600, in run_forever\n      self._run_once()\n    File \"/home/vvdiaz1/.pyenv/versions/3.10.6/lib/python3.10/asyncio/base_events.py\", line 1896, in _run_once\n      handle._run()\n    File \"/home/vvdiaz1/.pyenv/versions/3.10.6/lib/python3.10/asyncio/events.py\", line 80, in _run\n      self._context.run(self._callback, *self._args)\n    File \"/home/vvdiaz1/.pyenv/versions/lewagon/lib/python3.10/site-packages/ipykernel/kernelbase.py\", line 510, in dispatch_queue\n      await self.process_one()\n    File \"/home/vvdiaz1/.pyenv/versions/lewagon/lib/python3.10/site-packages/ipykernel/kernelbase.py\", line 499, in process_one\n      await dispatch(*args)\n    File \"/home/vvdiaz1/.pyenv/versions/lewagon/lib/python3.10/site-packages/ipykernel/kernelbase.py\", line 406, in dispatch_shell\n      await result\n    File \"/home/vvdiaz1/.pyenv/versions/lewagon/lib/python3.10/site-packages/ipykernel/kernelbase.py\", line 730, in execute_request\n      reply_content = await reply_content\n    File \"/home/vvdiaz1/.pyenv/versions/lewagon/lib/python3.10/site-packages/ipykernel/ipkernel.py\", line 383, in do_execute\n      res = shell.run_cell(\n    File \"/home/vvdiaz1/.pyenv/versions/lewagon/lib/python3.10/site-packages/ipykernel/zmqshell.py\", line 528, in run_cell\n      return super().run_cell(*args, **kwargs)\n    File \"/home/vvdiaz1/.pyenv/versions/lewagon/lib/python3.10/site-packages/IPython/core/interactiveshell.py\", line 2885, in run_cell\n      result = self._run_cell(\n    File \"/home/vvdiaz1/.pyenv/versions/lewagon/lib/python3.10/site-packages/IPython/core/interactiveshell.py\", line 2940, in _run_cell\n      return runner(coro)\n    File \"/home/vvdiaz1/.pyenv/versions/lewagon/lib/python3.10/site-packages/IPython/core/async_helpers.py\", line 129, in _pseudo_sync_runner\n      coro.send(None)\n    File \"/home/vvdiaz1/.pyenv/versions/lewagon/lib/python3.10/site-packages/IPython/core/interactiveshell.py\", line 3139, in run_cell_async\n      has_raised = await self.run_ast_nodes(code_ast.body, cell_name,\n    File \"/home/vvdiaz1/.pyenv/versions/lewagon/lib/python3.10/site-packages/IPython/core/interactiveshell.py\", line 3318, in run_ast_nodes\n      if await self.run_code(code, result, async_=asy):\n    File \"/home/vvdiaz1/.pyenv/versions/lewagon/lib/python3.10/site-packages/IPython/core/interactiveshell.py\", line 3378, in run_code\n      exec(code_obj, self.user_global_ns, self.user_ns)\n    File \"/tmp/ipykernel_3689/2842717622.py\", line 1, in <module>\n      history = model.fit_generator(\n    File \"/home/vvdiaz1/.pyenv/versions/lewagon/lib/python3.10/site-packages/keras/engine/training.py\", line 2507, in fit_generator\n      return self.fit(\n    File \"/home/vvdiaz1/.pyenv/versions/lewagon/lib/python3.10/site-packages/keras/utils/traceback_utils.py\", line 65, in error_handler\n      return fn(*args, **kwargs)\n    File \"/home/vvdiaz1/.pyenv/versions/lewagon/lib/python3.10/site-packages/keras/engine/training.py\", line 1564, in fit\n      tmp_logs = self.train_function(iterator)\n    File \"/home/vvdiaz1/.pyenv/versions/lewagon/lib/python3.10/site-packages/keras/engine/training.py\", line 1160, in train_function\n      return step_function(self, iterator)\n    File \"/home/vvdiaz1/.pyenv/versions/lewagon/lib/python3.10/site-packages/keras/engine/training.py\", line 1146, in step_function\n      outputs = model.distribute_strategy.run(run_step, args=(data,))\n    File \"/home/vvdiaz1/.pyenv/versions/lewagon/lib/python3.10/site-packages/keras/engine/training.py\", line 1135, in run_step\n      outputs = model.train_step(data)\n    File \"/home/vvdiaz1/.pyenv/versions/lewagon/lib/python3.10/site-packages/keras/engine/training.py\", line 994, in train_step\n      loss = self.compute_loss(x, y, y_pred, sample_weight)\n    File \"/home/vvdiaz1/.pyenv/versions/lewagon/lib/python3.10/site-packages/keras/engine/training.py\", line 1052, in compute_loss\n      return self.compiled_loss(\n    File \"/home/vvdiaz1/.pyenv/versions/lewagon/lib/python3.10/site-packages/keras/engine/compile_utils.py\", line 265, in __call__\n      loss_value = loss_obj(y_t, y_p, sample_weight=sw)\n    File \"/home/vvdiaz1/.pyenv/versions/lewagon/lib/python3.10/site-packages/keras/losses.py\", line 152, in __call__\n      losses = call_fn(y_true, y_pred)\n    File \"/home/vvdiaz1/.pyenv/versions/lewagon/lib/python3.10/site-packages/keras/losses.py\", line 272, in call\n      return ag_fn(y_true, y_pred, **self._fn_kwargs)\n    File \"/home/vvdiaz1/.pyenv/versions/lewagon/lib/python3.10/site-packages/keras/losses.py\", line 1990, in categorical_crossentropy\n      return backend.categorical_crossentropy(\n    File \"/home/vvdiaz1/.pyenv/versions/lewagon/lib/python3.10/site-packages/keras/backend.py\", line 5535, in categorical_crossentropy\n      return tf.nn.softmax_cross_entropy_with_logits(\nNode: 'categorical_crossentropy/softmax_cross_entropy_with_logits'\nlogits and labels must be broadcastable: logits_size=[5,7] labels_size=[5,4]\n\t [[{{node categorical_crossentropy/softmax_cross_entropy_with_logits}}]] [Op:__inference_train_function_923]"
     ]
    }
   ],
   "source": [
    "history = model.fit(\n",
    "             train_generator,\n",
    "             steps_per_epoch = 5,\n",
    "            #  epochs = 30,\n",
    "             callbacks = EarlyStopping(patience = 5, restore_best_weights=True),\n",
    "             validation_data = val_generator,\n",
    "             validation_steps = 15)"
   ]
  },
  {
   "cell_type": "code",
   "execution_count": null,
   "metadata": {},
   "outputs": [],
   "source": [
    "model.evaluate_generator(val_generator,verbose = 0)"
   ]
  },
  {
   "cell_type": "code",
   "execution_count": null,
   "metadata": {},
   "outputs": [],
   "source": [
    "model.evaluate_generator(test_generator,verbose = 0)"
   ]
  },
  {
   "attachments": {},
   "cell_type": "markdown",
   "metadata": {},
   "source": [
    "### Ahora con transfer learning"
   ]
  },
  {
   "cell_type": "code",
   "execution_count": null,
   "metadata": {},
   "outputs": [],
   "source": []
  }
 ],
 "metadata": {
  "kernelspec": {
   "display_name": "Python 3",
   "language": "python",
   "name": "python3"
  },
  "language_info": {
   "codemirror_mode": {
    "name": "ipython",
    "version": 3
   },
   "file_extension": ".py",
   "mimetype": "text/x-python",
   "name": "python",
   "nbconvert_exporter": "python",
   "pygments_lexer": "ipython3",
   "version": "3.10.6 (main, Nov 14 2022, 14:31:41) [GCC 11.3.0]"
  },
  "orig_nbformat": 4,
  "vscode": {
   "interpreter": {
    "hash": "b766fd3b13a0d26155c4f537c73e84d8eae09f0b10c7fe7a8fb4eec6202f4718"
   }
  }
 },
 "nbformat": 4,
 "nbformat_minor": 2
}
